<robot name="Newlife">
<link name="base_footprint"/>
<link name="Disc1">
  <visual>
    <geometry>
      <cylinder radius="0.05" length="0.05"/>
    </geometry>
    <material name="LightGrey">
      <color rgba="0.7 0.7 0.7 1.0"/>
    </material>
  </visual>
</link>
<link name="Disc2">
  <visual>
    <geometry>
      <cylinder radius="0.05" length="0.05"/>
    </geometry>
    <material name="LightGrey">
      <color rgba="0.7 0.7 0.7 1.0"/>
    </material>
  </visual>
</link>
<link name="Rod1">
  <visual>
    <geometry> 
      <box size="0.02 1.0 0.01" />
    </geometry>
    <material name="a">
      <color rgba="0.0 0.0 0.0 1.0"/>
    </material>
     <inertial>
    <mass value="1.0"/>
    <origin xyz="0.0 0.0 0.0" rpy="0.0 0.0 0.0"/>
    <inertia ixx="0.0" ixy="0.0" ixz="0.0" iyy="0.0" iyz="0.0" izz="2.0"/>
    </inertial>
  </visual>
</link>
<link name="Rod2">
  <visual>
    <geometry> 
      <box size="0.02 1.0 0.01" />
    </geometry>
    <material name="a">
      <color rgba="0.0 0.0 0.0 1.0"/>
    </material>
     <inertial>
    <mass value="1.0"/>
    <origin xyz="0.0 0.0 0.0" rpy="0.0 0.0 0.0"/>
    <inertia ixx="0.0" ixy="0.0" ixz="0.0" iyy="0.0" iyz="0.0" izz="2.0"/>
    </inertial>
  </visual>
</link>
<link name="plate">
  <visual>
    <geometry> 
      <box size="0.04 0.25 0.01" />
    </geometry>
    <material name="LightGrey">
      <color rgba="0.7 0.7 0.7 1.0"/>
    </material>
  </visual>
</link>
<joint name="joint1" type="continuous">
  <parent link="base_footprint"/>
  <child link="Disc1"/>
  <origin xyz="0.0 0.0 0.0" rpy="0.0 0.0 0.0"/>
  <axis xyz="0.0 0.0 1.0"/>
</joint>
<joint name="joint2" type="fixed">
  <parent link="Disc1"/>
  <child link="Rod1"/>
  <axis xyz="0 0.0 0"/>
  <origin xyz="0 0.5 0" rpy="0 0 0"/>
</joint>
<joint name="joint3" type="continuous">
  <parent link="Rod1"/>
  <child link="Disc2"/>
  <origin xyz="0.0 0.5 0.0" rpy="0.0 0.0 0.0"/>
  <axis xyz="0.0 0.0 1.0"/>
  
</joint>
<joint name="joint4" type="fixed">
  <parent link="Disc2"/>
  <child link="Rod2"/>
  <origin xyz="0.0 0.5 0.0" rpy="0.0 0.0 0.0"/>
</joint>
<joint name="joint5" type="fixed">
  <parent link="Rod2"/>
  <child link="plate"/>
  <origin xyz="0.0 0.6 0.0" rpy="0.0 0.0 0.0"/>
</joint>

</robot>